2024-10-03 17:19:18,929 INFO    StreamThr :2712 [internal.py:wandb_internal():87] W&B internal server running at pid: 2712, started at: 2024-10-03 17:19:18.925999
2024-10-03 17:19:18,931 DEBUG   HandlerThread:2712 [handler.py:handle_request():144] handle_request: status
2024-10-03 17:19:18,954 INFO    WriterThread:2712 [datastore.py:open_for_write():85] open: C:\Users\shanthod\OneDrive - Singapore Management University\Desktop\codes\wandb\run-20241003_171918-4bq4x6cu\run-4bq4x6cu.wandb
2024-10-03 17:19:18,957 DEBUG   SenderThread:2712 [sender.py:send():336] send: header
2024-10-03 17:19:18,972 DEBUG   SenderThread:2712 [sender.py:send():336] send: run
2024-10-03 17:19:22,450 INFO    SenderThread:2712 [retry.py:__call__():172] Retry attempt failed:
Traceback (most recent call last):
  File "C:\Users\shanthod\AppData\Local\Programs\Python\Python39\lib\site-packages\urllib3\connection.py", line 174, in _new_conn
    conn = connection.create_connection(
  File "C:\Users\shanthod\AppData\Local\Programs\Python\Python39\lib\site-packages\urllib3\util\connection.py", line 72, in create_connection
    for res in socket.getaddrinfo(host, port, family, socket.SOCK_STREAM):
  File "C:\Users\shanthod\AppData\Local\Programs\Python\Python39\lib\socket.py", line 953, in getaddrinfo
    for res in _socket.getaddrinfo(host, port, family, type, proto, flags):
socket.gaierror: [Errno 11001] getaddrinfo failed

During handling of the above exception, another exception occurred:

Traceback (most recent call last):
  File "C:\Users\shanthod\AppData\Local\Programs\Python\Python39\lib\site-packages\urllib3\connectionpool.py", line 703, in urlopen
    httplib_response = self._make_request(
  File "C:\Users\shanthod\AppData\Local\Programs\Python\Python39\lib\site-packages\urllib3\connectionpool.py", line 386, in _make_request
    self._validate_conn(conn)
  File "C:\Users\shanthod\AppData\Local\Programs\Python\Python39\lib\site-packages\urllib3\connectionpool.py", line 1042, in _validate_conn
    conn.connect()
  File "C:\Users\shanthod\AppData\Local\Programs\Python\Python39\lib\site-packages\urllib3\connection.py", line 358, in connect
    self.sock = conn = self._new_conn()
  File "C:\Users\shanthod\AppData\Local\Programs\Python\Python39\lib\site-packages\urllib3\connection.py", line 186, in _new_conn
    raise NewConnectionError(
urllib3.exceptions.NewConnectionError: <urllib3.connection.HTTPSConnection object at 0x000002560C220D30>: Failed to establish a new connection: [Errno 11001] getaddrinfo failed

During handling of the above exception, another exception occurred:

Traceback (most recent call last):
  File "C:\Users\shanthod\AppData\Local\Programs\Python\Python39\lib\site-packages\requests\adapters.py", line 440, in send
    resp = conn.urlopen(
  File "C:\Users\shanthod\AppData\Local\Programs\Python\Python39\lib\site-packages\urllib3\connectionpool.py", line 787, in urlopen
    retries = retries.increment(
  File "C:\Users\shanthod\AppData\Local\Programs\Python\Python39\lib\site-packages\urllib3\util\retry.py", line 592, in increment
    raise MaxRetryError(_pool, url, error or ResponseError(cause))
urllib3.exceptions.MaxRetryError: HTTPSConnectionPool(host='api.wandb.ai', port=443): Max retries exceeded with url: /graphql (Caused by NewConnectionError('<urllib3.connection.HTTPSConnection object at 0x000002560C220D30>: Failed to establish a new connection: [Errno 11001] getaddrinfo failed'))

During handling of the above exception, another exception occurred:

Traceback (most recent call last):
  File "C:\Users\shanthod\AppData\Local\Programs\Python\Python39\lib\site-packages\wandb\sdk\lib\retry.py", line 131, in __call__
    result = self._call_fn(*args, **kwargs)
  File "C:\Users\shanthod\AppData\Local\Programs\Python\Python39\lib\site-packages\wandb\sdk\internal\internal_api.py", line 242, in execute
    return self.client.execute(*args, **kwargs)  # type: ignore
  File "C:\Users\shanthod\AppData\Local\Programs\Python\Python39\lib\site-packages\wandb\vendor\gql-0.2.0\wandb_gql\client.py", line 52, in execute
    result = self._get_result(document, *args, **kwargs)
  File "C:\Users\shanthod\AppData\Local\Programs\Python\Python39\lib\site-packages\wandb\vendor\gql-0.2.0\wandb_gql\client.py", line 60, in _get_result
    return self.transport.execute(document, *args, **kwargs)
  File "C:\Users\shanthod\AppData\Local\Programs\Python\Python39\lib\site-packages\wandb\vendor\gql-0.2.0\wandb_gql\transport\requests.py", line 38, in execute
    request = requests.post(self.url, **post_args)
  File "C:\Users\shanthod\AppData\Local\Programs\Python\Python39\lib\site-packages\requests\api.py", line 117, in post
    return request('post', url, data=data, json=json, **kwargs)
  File "C:\Users\shanthod\AppData\Local\Programs\Python\Python39\lib\site-packages\requests\api.py", line 61, in request
    return session.request(method=method, url=url, **kwargs)
  File "C:\Users\shanthod\AppData\Local\Programs\Python\Python39\lib\site-packages\requests\sessions.py", line 529, in request
    resp = self.send(prep, **send_kwargs)
  File "C:\Users\shanthod\AppData\Local\Programs\Python\Python39\lib\site-packages\requests\sessions.py", line 645, in send
    r = adapter.send(request, **kwargs)
  File "C:\Users\shanthod\AppData\Local\Programs\Python\Python39\lib\site-packages\requests\adapters.py", line 519, in send
    raise ConnectionError(e, request=request)
requests.exceptions.ConnectionError: HTTPSConnectionPool(host='api.wandb.ai', port=443): Max retries exceeded with url: /graphql (Caused by NewConnectionError('<urllib3.connection.HTTPSConnection object at 0x000002560C220D30>: Failed to establish a new connection: [Errno 11001] getaddrinfo failed'))
2024-10-03 17:19:24,019 DEBUG   HandlerThread:2712 [handler.py:handle_request():144] handle_request: keepalive
2024-10-03 17:23:02,983 INFO    StreamThr :2712 [internal.py:wandb_internal():87] W&B internal server running at pid: 2712, started at: 2024-10-03 17:23:02.979371
2024-10-03 17:23:02,986 DEBUG   HandlerThread:2712 [handler.py:handle_request():144] handle_request: status
2024-10-03 17:23:03,000 INFO    WriterThread:2712 [datastore.py:open_for_write():85] open: C:\Users\shanthod\OneDrive - Singapore Management University\Desktop\codes\wandb\run-20241003_172302-28md5u49\run-28md5u49.wandb
2024-10-03 17:23:03,003 DEBUG   SenderThread:2712 [sender.py:send():336] send: header
2024-10-03 17:23:03,015 DEBUG   SenderThread:2712 [sender.py:send():336] send: run
2024-10-03 17:23:06,648 INFO    SenderThread:2712 [retry.py:__call__():172] Retry attempt failed:
Traceback (most recent call last):
  File "C:\Users\shanthod\AppData\Local\Programs\Python\Python39\lib\site-packages\urllib3\connection.py", line 174, in _new_conn
    conn = connection.create_connection(
  File "C:\Users\shanthod\AppData\Local\Programs\Python\Python39\lib\site-packages\urllib3\util\connection.py", line 72, in create_connection
    for res in socket.getaddrinfo(host, port, family, socket.SOCK_STREAM):
  File "C:\Users\shanthod\AppData\Local\Programs\Python\Python39\lib\socket.py", line 953, in getaddrinfo
    for res in _socket.getaddrinfo(host, port, family, type, proto, flags):
socket.gaierror: [Errno 11001] getaddrinfo failed

During handling of the above exception, another exception occurred:

Traceback (most recent call last):
  File "C:\Users\shanthod\AppData\Local\Programs\Python\Python39\lib\site-packages\urllib3\connectionpool.py", line 703, in urlopen
    httplib_response = self._make_request(
  File "C:\Users\shanthod\AppData\Local\Programs\Python\Python39\lib\site-packages\urllib3\connectionpool.py", line 386, in _make_request
    self._validate_conn(conn)
  File "C:\Users\shanthod\AppData\Local\Programs\Python\Python39\lib\site-packages\urllib3\connectionpool.py", line 1042, in _validate_conn
    conn.connect()
  File "C:\Users\shanthod\AppData\Local\Programs\Python\Python39\lib\site-packages\urllib3\connection.py", line 358, in connect
    self.sock = conn = self._new_conn()
  File "C:\Users\shanthod\AppData\Local\Programs\Python\Python39\lib\site-packages\urllib3\connection.py", line 186, in _new_conn
    raise NewConnectionError(
urllib3.exceptions.NewConnectionError: <urllib3.connection.HTTPSConnection object at 0x000002560C326C10>: Failed to establish a new connection: [Errno 11001] getaddrinfo failed

During handling of the above exception, another exception occurred:

Traceback (most recent call last):
  File "C:\Users\shanthod\AppData\Local\Programs\Python\Python39\lib\site-packages\requests\adapters.py", line 440, in send
    resp = conn.urlopen(
  File "C:\Users\shanthod\AppData\Local\Programs\Python\Python39\lib\site-packages\urllib3\connectionpool.py", line 787, in urlopen
    retries = retries.increment(
  File "C:\Users\shanthod\AppData\Local\Programs\Python\Python39\lib\site-packages\urllib3\util\retry.py", line 592, in increment
    raise MaxRetryError(_pool, url, error or ResponseError(cause))
urllib3.exceptions.MaxRetryError: HTTPSConnectionPool(host='api.wandb.ai', port=443): Max retries exceeded with url: /graphql (Caused by NewConnectionError('<urllib3.connection.HTTPSConnection object at 0x000002560C326C10>: Failed to establish a new connection: [Errno 11001] getaddrinfo failed'))

During handling of the above exception, another exception occurred:

Traceback (most recent call last):
  File "C:\Users\shanthod\AppData\Local\Programs\Python\Python39\lib\site-packages\wandb\sdk\lib\retry.py", line 131, in __call__
    result = self._call_fn(*args, **kwargs)
  File "C:\Users\shanthod\AppData\Local\Programs\Python\Python39\lib\site-packages\wandb\sdk\internal\internal_api.py", line 242, in execute
    return self.client.execute(*args, **kwargs)  # type: ignore
  File "C:\Users\shanthod\AppData\Local\Programs\Python\Python39\lib\site-packages\wandb\vendor\gql-0.2.0\wandb_gql\client.py", line 52, in execute
    result = self._get_result(document, *args, **kwargs)
  File "C:\Users\shanthod\AppData\Local\Programs\Python\Python39\lib\site-packages\wandb\vendor\gql-0.2.0\wandb_gql\client.py", line 60, in _get_result
    return self.transport.execute(document, *args, **kwargs)
  File "C:\Users\shanthod\AppData\Local\Programs\Python\Python39\lib\site-packages\wandb\vendor\gql-0.2.0\wandb_gql\transport\requests.py", line 38, in execute
    request = requests.post(self.url, **post_args)
  File "C:\Users\shanthod\AppData\Local\Programs\Python\Python39\lib\site-packages\requests\api.py", line 117, in post
    return request('post', url, data=data, json=json, **kwargs)
  File "C:\Users\shanthod\AppData\Local\Programs\Python\Python39\lib\site-packages\requests\api.py", line 61, in request
    return session.request(method=method, url=url, **kwargs)
  File "C:\Users\shanthod\AppData\Local\Programs\Python\Python39\lib\site-packages\requests\sessions.py", line 529, in request
    resp = self.send(prep, **send_kwargs)
  File "C:\Users\shanthod\AppData\Local\Programs\Python\Python39\lib\site-packages\requests\sessions.py", line 645, in send
    r = adapter.send(request, **kwargs)
  File "C:\Users\shanthod\AppData\Local\Programs\Python\Python39\lib\site-packages\requests\adapters.py", line 519, in send
    raise ConnectionError(e, request=request)
requests.exceptions.ConnectionError: HTTPSConnectionPool(host='api.wandb.ai', port=443): Max retries exceeded with url: /graphql (Caused by NewConnectionError('<urllib3.connection.HTTPSConnection object at 0x000002560C326C10>: Failed to establish a new connection: [Errno 11001] getaddrinfo failed'))
2024-10-03 17:23:08,065 DEBUG   HandlerThread:2712 [handler.py:handle_request():144] handle_request: keepalive
2024-10-03 17:23:13,110 DEBUG   HandlerThread:2712 [handler.py:handle_request():144] handle_request: keepalive
2024-10-03 17:23:18,123 DEBUG   HandlerThread:2712 [handler.py:handle_request():144] handle_request: keepalive
2024-10-03 17:23:23,166 DEBUG   HandlerThread:2712 [handler.py:handle_request():144] handle_request: keepalive
2024-10-03 17:23:28,177 DEBUG   HandlerThread:2712 [handler.py:handle_request():144] handle_request: keepalive
2024-10-03 17:23:33,185 DEBUG   HandlerThread:2712 [handler.py:handle_request():144] handle_request: keepalive
2024-10-03 17:23:38,196 DEBUG   HandlerThread:2712 [handler.py:handle_request():144] handle_request: keepalive
2024-10-03 17:23:43,228 DEBUG   HandlerThread:2712 [handler.py:handle_request():144] handle_request: keepalive
2024-10-03 17:23:48,257 DEBUG   HandlerThread:2712 [handler.py:handle_request():144] handle_request: keepalive
2024-10-03 17:23:53,275 DEBUG   HandlerThread:2712 [handler.py:handle_request():144] handle_request: keepalive
2024-10-03 17:23:58,321 DEBUG   HandlerThread:2712 [handler.py:handle_request():144] handle_request: keepalive
2024-10-03 17:24:03,354 DEBUG   HandlerThread:2712 [handler.py:handle_request():144] handle_request: cancel
2024-10-03 17:24:03,354 DEBUG   HandlerThread:2712 [handler.py:handle_request():144] handle_request: cancel
2024-10-03 17:24:03,355 DEBUG   SenderThread:2712 [sender.py:send():345] Record cancelled: run
2024-10-03 17:24:03,355 DEBUG   HandlerThread:2712 [handler.py:handle_request():144] handle_request: status_report
2024-10-03 17:24:07,351 INFO    MainThread:2712 [internal.py:handle_exit():77] Internal process exited
2024-10-03 17:24:07,351 INFO    MainThread:2712 [internal.py:handle_exit():77] Internal process exited
