2023-03-04 01:21:59 ERROR dropped chunk HTTPSConnectionPool(host='api.wandb.ai', port=443): Max retries exceeded with url: /files/shan_proj/ssl-relation-prediction/adlvovne/file_stream (Caused by NewConnectionError('<urllib3.connection.HTTPSConnection object at 0x0000024A0E6BD8E0>: Failed to establish a new connection: [Errno 11001] getaddrinfo failed'))
NoneType: None
2023-03-04 03:35:39 ERROR dropped chunk HTTPSConnectionPool(host='api.wandb.ai', port=443): Max retries exceeded with url: /files/shan_proj/ssl-relation-prediction/adlvovne/file_stream (Caused by NewConnectionError('<urllib3.connection.HTTPSConnection object at 0x0000024A0E639D60>: Failed to establish a new connection: [Errno 11001] getaddrinfo failed'))
NoneType: None
2023-03-05 21:01:23 ERROR dropped chunk HTTPSConnectionPool(host='api.wandb.ai', port=443): Max retries exceeded with url: /files/shan_proj/ssl-relation-prediction/adlvovne/file_stream (Caused by NewConnectionError('<urllib3.connection.HTTPSConnection object at 0x0000024A0E617820>: Failed to establish a new connection: [Errno 11001] getaddrinfo failed'))
NoneType: None
2023-03-24 16:02:11 WARNING Retrying (Retry(total=2, connect=None, read=None, redirect=None, status=None)) after connection broken by 'NewConnectionError('<urllib3.connection.HTTPSConnection object at 0x0000024D4BFC1160>: Failed to establish a new connection: [Errno 11001] getaddrinfo failed')': /api/5288891/envelope/
2023-03-24 16:02:11 WARNING Retrying (Retry(total=1, connect=None, read=None, redirect=None, status=None)) after connection broken by 'NewConnectionError('<urllib3.connection.HTTPSConnection object at 0x0000024D4BFC12B0>: Failed to establish a new connection: [Errno 11001] getaddrinfo failed')': /api/5288891/envelope/
2023-03-24 16:02:11 WARNING Retrying (Retry(total=0, connect=None, read=None, redirect=None, status=None)) after connection broken by 'NewConnectionError('<urllib3.connection.HTTPSConnection object at 0x0000024D4BFC11F0>: Failed to establish a new connection: [Errno 11001] getaddrinfo failed')': /api/5288891/envelope/
2023-03-24 16:11:11 WARNING Retrying (Retry(total=2, connect=None, read=None, redirect=None, status=None)) after connection broken by 'NewConnectionError('<urllib3.connection.HTTPSConnection object at 0x0000024D4BF99C40>: Failed to establish a new connection: [Errno 11001] getaddrinfo failed')': /api/5288891/envelope/
2023-03-24 16:11:11 WARNING Retrying (Retry(total=1, connect=None, read=None, redirect=None, status=None)) after connection broken by 'NewConnectionError('<urllib3.connection.HTTPSConnection object at 0x0000024D4C006070>: Failed to establish a new connection: [Errno 11001] getaddrinfo failed')': /api/5288891/envelope/
2023-03-24 16:11:11 WARNING Retrying (Retry(total=0, connect=None, read=None, redirect=None, status=None)) after connection broken by 'NewConnectionError('<urllib3.connection.HTTPSConnection object at 0x0000024D4C006190>: Failed to establish a new connection: [Errno 11001] getaddrinfo failed')': /api/5288891/envelope/
2023-03-24 19:58:04 ERROR dropped chunk HTTPSConnectionPool(host='api.wandb.ai', port=443): Max retries exceeded with url: /files/shan_proj/ssl-relation-prediction/bllagkfy/file_stream (Caused by NewConnectionError('<urllib3.connection.HTTPSConnection object at 0x0000024D4BFF77F0>: Failed to establish a new connection: [Errno 11001] getaddrinfo failed'))
NoneType: None
2024-10-03 17:24:02 WARNING Retrying (Retry(total=2, connect=None, read=None, redirect=None, status=None)) after connection broken by 'NewConnectionError('<urllib3.connection.HTTPSConnection object at 0x000002560C326AC0>: Failed to establish a new connection: [Errno 11001] getaddrinfo failed')': /api/5288891/envelope/
2024-10-03 17:24:02 WARNING Retrying (Retry(total=1, connect=None, read=None, redirect=None, status=None)) after connection broken by 'NewConnectionError('<urllib3.connection.HTTPSConnection object at 0x000002560C336070>: Failed to establish a new connection: [Errno 11001] getaddrinfo failed')': /api/5288891/envelope/
2024-10-03 17:24:02 WARNING Retrying (Retry(total=0, connect=None, read=None, redirect=None, status=None)) after connection broken by 'NewConnectionError('<urllib3.connection.HTTPSConnection object at 0x000002560C336130>: Failed to establish a new connection: [Errno 11001] getaddrinfo failed')': /api/5288891/envelope/
