2023-03-05 21:24:34,609 INFO    MainThread:40584 [wandb_setup.py:_flush():68] Configure stats pid to 40584
2023-03-05 21:24:34,610 INFO    MainThread:40584 [wandb_setup.py:_flush():68] Loading settings from C:\Users\shanthod\.config\wandb\settings
2023-03-05 21:24:34,610 INFO    MainThread:40584 [wandb_setup.py:_flush():68] Loading settings from C:\Users\shanthod\Downloads\ssl-relation-prediction-main\ssl-relation-prediction-main\src\wandb\settings
2023-03-05 21:24:34,610 WARNING MainThread:40584 [wandb_setup.py:_flush():68] Unknown environment variable: WANDB_SERVICE
2023-03-05 21:24:34,610 INFO    MainThread:40584 [wandb_setup.py:_flush():68] Loading settings from environment variables: {'_require_service': 'True'}
2023-03-05 21:24:34,611 INFO    MainThread:40584 [wandb_setup.py:_flush():68] Inferring run settings from compute environment: {'program_relpath': 'main.py', 'program': 'C:\\Users\\shanthod\\Downloads\\ssl-relation-prediction-main\\ssl-relation-prediction-main\\src\\main.py'}
2023-03-05 21:24:34,612 INFO    MainThread:40584 [wandb_init.py:_log_setup():492] Logging user logs to C:\Users\shanthod\Downloads\ssl-relation-prediction-main\ssl-relation-prediction-main\src\wandb\run-20230305_212434-dz8v60hd\logs\debug.log
2023-03-05 21:24:34,613 INFO    MainThread:40584 [wandb_init.py:_log_setup():493] Logging internal logs to C:\Users\shanthod\Downloads\ssl-relation-prediction-main\ssl-relation-prediction-main\src\wandb\run-20230305_212434-dz8v60hd\logs\debug-internal.log
2023-03-05 21:24:34,613 INFO    MainThread:40584 [wandb_init.py:init():532] calling init triggers
2023-03-05 21:24:34,613 INFO    MainThread:40584 [wandb_init.py:init():538] wandb.init called with sweep_config: {}
config: {}
2023-03-05 21:24:34,613 INFO    MainThread:40584 [wandb_init.py:init():588] starting backend
2023-03-05 21:24:34,613 INFO    MainThread:40584 [wandb_init.py:init():592] setting up manager
2023-03-05 21:24:34,621 INFO    MainThread:40584 [backend.py:_multiprocessing_setup():106] multiprocessing start_methods=spawn, using: spawn
2023-03-05 21:24:34,631 INFO    MainThread:40584 [wandb_init.py:init():599] backend started and connected
2023-03-05 21:24:34,634 INFO    MainThread:40584 [wandb_init.py:init():687] updated telemetry
2023-03-05 21:24:34,646 INFO    MainThread:40584 [wandb_init.py:init():727] communicating run to backend with 60.0 second timeout
2023-03-05 21:25:35,257 ERROR   MainThread:40584 [wandb_init.py:init():741] backend process timed out, exiting...
encountered error: Error communicating with wandb process, exiting...
For more info see: https://docs.wandb.ai/library/init#init-start-error
2023-03-05 21:25:35,284 ERROR   MainThread:40584 [wandb_init.py:init():1160] error
Traceback (most recent call last):
  File "C:\Users\shanthod\AppData\Local\Programs\Python\Python39\lib\site-packages\wandb\sdk\wandb_init.py", line 1133, in init
    run = wi.init()
  File "C:\Users\shanthod\AppData\Local\Programs\Python\Python39\lib\site-packages\wandb\sdk\wandb_init.py", line 759, in init
    raise error
wandb.errors.CommError: Error communicating with wandb process, exiting...
For more info see: https://docs.wandb.ai/library/init#init-start-error
