2023-03-05 21:22:26,421 INFO    StreamThr :1304 [internal.py:wandb_internal():87] W&B internal server running at pid: 1304, started at: 2023-03-05 21:22:26.420054
2023-03-05 21:22:26,424 DEBUG   HandlerThread:1304 [handler.py:handle_request():144] handle_request: status
2023-03-05 21:22:26,430 INFO    WriterThread:1304 [datastore.py:open_for_write():85] open: C:\Users\shanthod\Downloads\ssl-relation-prediction-main\ssl-relation-prediction-main\src\wandb\run-20230305_212226-r2fx5xwv\run-r2fx5xwv.wandb
2023-03-05 21:22:26,436 DEBUG   SenderThread:1304 [sender.py:send():336] send: header
2023-03-05 21:22:26,443 DEBUG   SenderThread:1304 [sender.py:send():336] send: run
2023-03-05 21:22:29,804 INFO    SenderThread:1304 [retry.py:__call__():172] Retry attempt failed:
Traceback (most recent call last):
  File "C:\Users\shanthod\AppData\Local\Programs\Python\Python39\lib\site-packages\urllib3\connection.py", line 174, in _new_conn
    conn = connection.create_connection(
  File "C:\Users\shanthod\AppData\Local\Programs\Python\Python39\lib\site-packages\urllib3\util\connection.py", line 72, in create_connection
    for res in socket.getaddrinfo(host, port, family, socket.SOCK_STREAM):
  File "C:\Users\shanthod\AppData\Local\Programs\Python\Python39\lib\socket.py", line 953, in getaddrinfo
    for res in _socket.getaddrinfo(host, port, family, type, proto, flags):
socket.gaierror: [Errno 11001] getaddrinfo failed

During handling of the above exception, another exception occurred:

Traceback (most recent call last):
  File "C:\Users\shanthod\AppData\Local\Programs\Python\Python39\lib\site-packages\urllib3\connectionpool.py", line 703, in urlopen
    httplib_response = self._make_request(
  File "C:\Users\shanthod\AppData\Local\Programs\Python\Python39\lib\site-packages\urllib3\connectionpool.py", line 386, in _make_request
    self._validate_conn(conn)
  File "C:\Users\shanthod\AppData\Local\Programs\Python\Python39\lib\site-packages\urllib3\connectionpool.py", line 1042, in _validate_conn
    conn.connect()
  File "C:\Users\shanthod\AppData\Local\Programs\Python\Python39\lib\site-packages\urllib3\connection.py", line 358, in connect
    self.sock = conn = self._new_conn()
  File "C:\Users\shanthod\AppData\Local\Programs\Python\Python39\lib\site-packages\urllib3\connection.py", line 186, in _new_conn
    raise NewConnectionError(
urllib3.exceptions.NewConnectionError: <urllib3.connection.HTTPSConnection object at 0x00000288EE62D670>: Failed to establish a new connection: [Errno 11001] getaddrinfo failed

During handling of the above exception, another exception occurred:

Traceback (most recent call last):
  File "C:\Users\shanthod\AppData\Local\Programs\Python\Python39\lib\site-packages\requests\adapters.py", line 440, in send
    resp = conn.urlopen(
  File "C:\Users\shanthod\AppData\Local\Programs\Python\Python39\lib\site-packages\urllib3\connectionpool.py", line 787, in urlopen
    retries = retries.increment(
  File "C:\Users\shanthod\AppData\Local\Programs\Python\Python39\lib\site-packages\urllib3\util\retry.py", line 592, in increment
    raise MaxRetryError(_pool, url, error or ResponseError(cause))
urllib3.exceptions.MaxRetryError: HTTPSConnectionPool(host='api.wandb.ai', port=443): Max retries exceeded with url: /graphql (Caused by NewConnectionError('<urllib3.connection.HTTPSConnection object at 0x00000288EE62D670>: Failed to establish a new connection: [Errno 11001] getaddrinfo failed'))

During handling of the above exception, another exception occurred:

Traceback (most recent call last):
  File "C:\Users\shanthod\AppData\Local\Programs\Python\Python39\lib\site-packages\wandb\sdk\lib\retry.py", line 131, in __call__
    result = self._call_fn(*args, **kwargs)
  File "C:\Users\shanthod\AppData\Local\Programs\Python\Python39\lib\site-packages\wandb\sdk\internal\internal_api.py", line 242, in execute
    return self.client.execute(*args, **kwargs)  # type: ignore
  File "C:\Users\shanthod\AppData\Local\Programs\Python\Python39\lib\site-packages\wandb\vendor\gql-0.2.0\wandb_gql\client.py", line 52, in execute
    result = self._get_result(document, *args, **kwargs)
  File "C:\Users\shanthod\AppData\Local\Programs\Python\Python39\lib\site-packages\wandb\vendor\gql-0.2.0\wandb_gql\client.py", line 60, in _get_result
    return self.transport.execute(document, *args, **kwargs)
  File "C:\Users\shanthod\AppData\Local\Programs\Python\Python39\lib\site-packages\wandb\vendor\gql-0.2.0\wandb_gql\transport\requests.py", line 38, in execute
    request = requests.post(self.url, **post_args)
  File "C:\Users\shanthod\AppData\Local\Programs\Python\Python39\lib\site-packages\requests\api.py", line 117, in post
    return request('post', url, data=data, json=json, **kwargs)
  File "C:\Users\shanthod\AppData\Local\Programs\Python\Python39\lib\site-packages\requests\api.py", line 61, in request
    return session.request(method=method, url=url, **kwargs)
  File "C:\Users\shanthod\AppData\Local\Programs\Python\Python39\lib\site-packages\requests\sessions.py", line 529, in request
    resp = self.send(prep, **send_kwargs)
  File "C:\Users\shanthod\AppData\Local\Programs\Python\Python39\lib\site-packages\requests\sessions.py", line 645, in send
    r = adapter.send(request, **kwargs)
  File "C:\Users\shanthod\AppData\Local\Programs\Python\Python39\lib\site-packages\requests\adapters.py", line 519, in send
    raise ConnectionError(e, request=request)
requests.exceptions.ConnectionError: HTTPSConnectionPool(host='api.wandb.ai', port=443): Max retries exceeded with url: /graphql (Caused by NewConnectionError('<urllib3.connection.HTTPSConnection object at 0x00000288EE62D670>: Failed to establish a new connection: [Errno 11001] getaddrinfo failed'))
2023-03-05 21:22:31,478 DEBUG   HandlerThread:1304 [handler.py:handle_request():144] handle_request: keepalive
2023-03-05 21:22:36,526 DEBUG   HandlerThread:1304 [handler.py:handle_request():144] handle_request: keepalive
2023-03-05 21:22:41,575 DEBUG   HandlerThread:1304 [handler.py:handle_request():144] handle_request: keepalive
2023-03-05 21:22:46,616 DEBUG   HandlerThread:1304 [handler.py:handle_request():144] handle_request: keepalive
2023-03-05 21:22:51,660 DEBUG   HandlerThread:1304 [handler.py:handle_request():144] handle_request: keepalive
2023-03-05 21:22:56,692 DEBUG   HandlerThread:1304 [handler.py:handle_request():144] handle_request: keepalive
2023-03-05 21:23:01,743 DEBUG   HandlerThread:1304 [handler.py:handle_request():144] handle_request: keepalive
2023-03-05 21:23:06,790 DEBUG   HandlerThread:1304 [handler.py:handle_request():144] handle_request: keepalive
2023-03-05 21:23:11,843 DEBUG   HandlerThread:1304 [handler.py:handle_request():144] handle_request: keepalive
2023-03-05 21:23:16,898 DEBUG   HandlerThread:1304 [handler.py:handle_request():144] handle_request: keepalive
2023-03-05 21:23:22,038 INFO    MainThread:1304 [internal.py:handle_exit():77] Internal process exited
